Workbook

Sheet po7335484_147586
A1: PO Number | B1: Release Number | C1: PO Date | D1: Dept # | E1: Retailers PO | F1: Requested Delivery Date | G1: Delivery Dates | H1: Ship Dates | I1: Cancel Date | J1: Carrier | K1: Carrier Details | L1: Ship To Location | M1: PO Line # | N1: Qty Ordered | O1: Unit of Measure | P1: Unit Price | Q1: Buyers Catalog or Stock Keeping # | R1: UPC/EAN | S1: Vendor Style | T1: Retail Price | U1: Product/Item Description | V1: Color | W1: Size | X1: Pack Size | Y1: Pack Size UOM | Z1: Number of Inner Packs | AA1: DC | AB1: Store # | AC1: Qty per Store # | AD1: Record Type | AE1: PO purpose | AF1: PO Type | AG1: Contract Number | AH1: Currency | AI1: Ship Status | AJ1: Letter of Credit | AK1: Vendor # | AL1: Division # | AM1: Cust Acct # | AN1: Customer Order # | AO1: Promo # | AP1: Ticket Description | AQ1: Other Info / #s | AR1: Frt Terms | AS1: Carrier Service Level | AT1: Payment Terms % | AU1: Payment Terms Disc Due Date | AV1: Payment Terms Disc Days Due | AW1: Payment Terms Net Due Date | AX1: Payment Terms Net Days | AY1: Payment Terms Disc Amt | AZ1: Payment Terms Desc | BA1: Contact Phone | BB1: Contact Fax | BC1: Contact Email | BD1: Allow/Charge Type | BE1: Allow/Charge Service | BF1: Allow/Charge Amt | BG1: Allow/Charge % | BH1: Allow/Charge Rate | BI1: Allow/Charge Qty | BJ1: Allow/Charge Desc | BK1: Ship To Name | BL1: Ship To Address 1 | BM1: Ship To Address 2 | BN1: Ship To City | BO1: Ship To State | BP1: Ship to Zip | BQ1: Ship To Country | BR1: Ship To Contact | BS1: Bill To Name | BT1: Bill To Address 1 | BU1: Bill To Address 2 | BV1: Bill To City | BW1: Bill To State | BX1: Bill To Zip | BY1: Bill To Country | BZ1: Bill To Contact | CA1: Buying Party Name | CB1: Buying Party Location | CC1: Buying Party Address 1 | CD1: Buying Party Address 2 | CE1: Buying Party City | CF1: Buying Party State | CG1: Buying Party Zip | CH1: Buying Party Country | CI1: Buying Party Contact | CJ1: Ultimate Location | CK1: Notes/Comments | CL1: Ship To Additional Name | CM1: Ship To Additional Name 2 | CN1: Bill To Additional Name | CO1: Bill To Additional Name 2 | CP1: Buyer Additional Name | CQ1: Buyer Additional Name 2 | CR1: GTIN | CS1: PO Total Amount | CT1: PO Total Weight | CU1: PO Total UOM | CV1: Shipping account number | CW1: Mark for Name | CX1: Mark for Address 1 | CY1: Mark for Address 2 | CZ1: Mark for City | DA1: Mark for State | DB1: Mark for Postal | DC1: Mark for Country | DD1: Shipping Container Code | DE1: National Drug Code | DF1: Expiration Date | DG1: Dist | DH1: Scheduled Quantity | DI1: Scheduled Qty UOM | DJ1: Required By Date | DK1: Must Arrive By | DL1: Entire Shipment | DM1: Agreement Number | DN1: Additional Vendor Part Number
A2: 7335484 | C2: 44560 | D2: 803 | E2: 7335484 | I2: 44602 | M2: 1 | N2: 18 | O2: Each | P2: 30 | R2: 810081709163 | S2: =_xlfn.XLOOKUP(R2,[1]UPC!$C:$C,[1]UPC!$A:$A,"???",0) -> WO-7223 | T2: 59.99 | V2: =_xlfn.XLOOKUP(R2,[1]UPC!$C:$C,[1]UPC!$E:$E,"???",0) -> Black | W2: =_xlfn.XLOOKUP(R2,[1]UPC!$C:$C,[1]UPC!$F:$F,"???",0) -> X Small | AA2: =_xlfn.XLOOKUP(AB2,'Bloomingdale''s Outlet'!C:C,'Bloomingdale''s Outlet'!B:B,"???",0) -> CL | AB2: 75 | AC2: 1 | AD2: D
A3: 7335484 | C3: 44560 | D3: 803 | E3: 7335484 | I3: 44602 | M3: 1 | N3: 18 | O3: Each | P3: 30 | R3: 810081709163 | S3: =_xlfn.XLOOKUP(R3,[1]UPC!$C:$C,[1]UPC!$A:$A,"???",0) -> WO-7223 | T3: 59.99 | V3: =_xlfn.XLOOKUP(R3,[1]UPC!$C:$C,[1]UPC!$E:$E,"???",0) -> Black | W3: =_xlfn.XLOOKUP(R3,[1]UPC!$C:$C,[1]UPC!$F:$F,"???",0) -> X Small | AA3: =_xlfn.XLOOKUP(AB3,'Bloomingdale''s Outlet'!C:C,'Bloomingdale''s Outlet'!B:B,"???",0) -> CL | AB3: 76 | AC3: 2 | AD3: D
A4: 7335484 | C4: 44560 | D4: 803 | E4: 7335484 | I4: 44602 | M4: 1 | N4: 18 | O4: Each | P4: 30 | R4: 810081709163 | S4: =_xlfn.XLOOKUP(R4,[1]UPC!$C:$C,[1]UPC!$A:$A,"???",0) -> WO-7223 | T4: 59.99 | V4: =_xlfn.XLOOKUP(R4,[1]UPC!$C:$C,[1]UPC!$E:$E,"???",0) -> Black | W4: =_xlfn.XLOOKUP(R4,[1]UPC!$C:$C,[1]UPC!$F:$F,"???",0) -> X Small | AA4: =_xlfn.XLOOKUP(AB4,'Bloomingdale''s Outlet'!C:C,'Bloomingdale''s Outlet'!B:B,"???",0) -> SC | AB4: 151 | AC4: 2 | AD4: D
A5: 7335484 | C5: 44560 | D5: 803 | E5: 7335484 | I5: 44602 | M5: 1 | N5: 18 | O5: Each | P5: 30 | R5: 810081709163 | S5: =_xlfn.XLOOKUP(R5,[1]UPC!$C:$C,[1]UPC!$A:$A,"???",0) -> WO-7223 | T5: 59.99 | V5: =_xlfn.XLOOKUP(R5,[1]UPC!$C:$C,[1]UPC!$E:$E,"???",0) -> Black | W5: =_xlfn.XLOOKUP(R5,[1]UPC!$C:$C,[1]UPC!$F:$F,"???",0) -> X Small | AA5: =_xlfn.XLOOKUP(AB5,'Bloomingdale''s Outlet'!C:C,'Bloomingdale''s Outlet'!B:B,"???",0) -> SC | AB5: 152 | AC5: 1 | AD5: D
A6: 7335484 | C6: 44560 | D6: 803 | E6: 7335484 | I6: 44602 | M6: 1 | N6: 18 | O6: Each | P6: 30 | R6: 810081709163 | S6: =_xlfn.XLOOKUP(R6,[1]UPC!$C:$C,[1]UPC!$A:$A,"???",0) -> WO-7223 | T6: 59.99 | V6: =_xlfn.XLOOKUP(R6,[1]UPC!$C:$C,[1]UPC!$E:$E,"???",0) -> Black | W6: =_xlfn.XLOOKUP(R6,[1]UPC!$C:$C,[1]UPC!$F:$F,"???",0) -> X Small | AA6: =_xlfn.XLOOKUP(AB6,'Bloomingdale''s Outlet'!C:C,'Bloomingdale''s Outlet'!B:B,"???",0) -> SC | AB6: 153 | AC6: 1 | AD6: D
A7: 7335484 | C7: 44560 | D7: 803 | E7: 7335484 | I7: 44602 | M7: 1 | N7: 18 | O7: Each | P7: 30 | R7: 810081709163 | S7: =_xlfn.XLOOKUP(R7,[1]UPC!$C:$C,[1]UPC!$A:$A,"???",0) -> WO-7223 | T7: 59.99 | V7: =_xlfn.XLOOKUP(R7,[1]UPC!$C:$C,[1]UPC!$E:$E,"???",0) -> Black | W7: =_xlfn.XLOOKUP(R7,[1]UPC!$C:$C,[1]UPC!$F:$F,"???",0) -> X Small | AA7: =_xlfn.XLOOKUP(AB7,'Bloomingdale''s Outlet'!C:C,'Bloomingdale''s Outlet'!B:B,"???",0) -> SC | AB7: 155 | AC7: 1 | AD7: D
A8: 7335484 | C8: 44560 | D8: 803 | E8: 7335484 | I8: 44602 | M8: 1 | N8: 18 | O8: Each | P8: 30 | R8: 810081709163 | S8: =_xlfn.XLOOKUP(R8,[1]UPC!$C:$C,[1]UPC!$A:$A,"???",0) -> WO-7223 | T8: 59.99 | V8: =_xlfn.XLOOKUP(R8,[1]UPC!$C:$C,[1]UPC!$E:$E,"???",0) -> Black | W8: =_xlfn.XLOOKUP(R8,[1]UPC!$C:$C,[1]UPC!$F:$F,"???",0) -> X Small | AA8: =_xlfn.XLOOKUP(AB8,'Bloomingdale''s Outlet'!C:C,'Bloomingdale''s Outlet'!B:B,"???",0) -> ST | AB8: 160 | AC8: 2 | AD8: D
A9: 7335484 | C9: 44560 | D9: 803 | E9: 7335484 | I9: 44602 | M9: 1 | N9: 18 | O9: Each | P9: 30 | R9: 810081709163 | S9: =_xlfn.XLOOKUP(R9,[1]UPC!$C:$C,[1]UPC!$A:$A,"???",0) -> WO-7223 | T9: 59.99 | V9: =_xlfn.XLOOKUP(R9,[1]UPC!$C:$C,[1]UPC!$E:$E,"???",0) -> Black | W9: =_xlfn.XLOOKUP(R9,[1]UPC!$C:$C,[1]UPC!$F:$F,"???",0) -> X Small | AA9: =_xlfn.XLOOKUP(AB9,'Bloomingdale''s Outlet'!C:C,'Bloomingdale''s Outlet'!B:B,"???",0) -> ST | AB9: 161 | AC9: 2 | AD9: D
A10: 7335484 | C10: 44560 | D10: 803 | E10: 7335484 | I10: 44602 | M10: 1 | N10: 18 | O10: Each | P10: 30 | R10: 810081709163 | S10: =_xlfn.XLOOKUP(R10,[1]UPC!$C:$C,[1]UPC!$A:$A,"???",0) -> WO-7223 | T10: 59.99 | V10: =_xlfn.XLOOKUP(R10,[1]UPC!$C:$C,[1]UPC!$E:$E,"???",0) -> Black | W10: =_xlfn.XLOOKUP(R10,[1]UPC!$C:$C,[1]UPC!$F:$F,"???",0) -> X Small | AA10: =_xlfn.XLOOKUP(AB10,'Bloomingdale''s Outlet'!C:C,'Bloomingdale''s Outlet'!B:B,"???",0) -> HU | AB10: 170 | AC10: 1 | AD10: D
A11: 7335484 | C11: 44560 | D11: 803 | E11: 7335484 | I11: 44602 | M11: 1 | N11: 18 | O11: Each | P11: 30 | R11: 810081709163 | S11: =_xlfn.XLOOKUP(R11,[1]UPC!$C:$C,[1]UPC!$A:$A,"???",0) -> WO-7223 | T11: 59.99 | V11: =_xlfn.XLOOKUP(R11,[1]UPC!$C:$C,[1]UPC!$E:$E,"???",0) -> Black | W11: =_xlfn.XLOOKUP(R11,[1]UPC!$C:$C,[1]UPC!$F:$F,"???",0) -> X Small | AA11: =_xlfn.XLOOKUP(AB11,'Bloomingdale''s Outlet'!C:C,'Bloomingdale''s Outlet'!B:B,"???",0) -> HU | AB11: 171 | AC11: 1 | AD11: D
A12: 7335484 | C12: 44560 | D12: 803 | E12: 7335484 | I12: 44602 | M12: 1 | N12: 18 | O12: Each | P12: 30 | R12: 810081709163 | S12: =_xlfn.XLOOKUP(R12,[1]UPC!$C:$C,[1]UPC!$A:$A,"???",0) -> WO-7223 | T12: 59.99 | V12: =_xlfn.XLOOKUP(R12,[1]UPC!$C:$C,[1]UPC!$E:$E,"???",0) -> Black | W12: =_xlfn.XLOOKUP(R12,[1]UPC!$C:$C,[1]UPC!$F:$F,"???",0) -> X Small | AA12: =_xlfn.XLOOKUP(AB12,'Bloomingdale''s Outlet'!C:C,'Bloomingdale''s Outlet'!B:B,"???",0) -> SW | AB12: 180 | AC12: 1 | AD12: D
A13: 7335484 | C13: 44560 | D13: 803 | E13: 7335484 | I13: 44602 | M13: 1 | N13: 18 | O13: Each | P13: 30 | R13: 810081709163 | S13: =_xlfn.XLOOKUP(R13,[1]UPC!$C:$C,[1]UPC!$A:$A,"???",0) -> WO-7223 | T13: 59.99 | V13: =_xlfn.XLOOKUP(R13,[1]UPC!$C:$C,[1]UPC!$E:$E,"???",0) -> Black | W13: =_xlfn.XLOOKUP(R13,[1]UPC!$C:$C,[1]UPC!$F:$F,"???",0) -> X Small | AA13: =_xlfn.XLOOKUP(AB13,'Bloomingdale''s Outlet'!C:C,'Bloomingdale''s Outlet'!B:B,"???",0) -> HA | AB13: 190 | AC13: 1 | AD13: D
... A366: 7335484 | C366: 44560 | D366: 803 | E366: 7335484 | I366: 44602 | M366: 25 | N366: 18 | O366: Each | P366: 30 | R366: 810094067472 | S366: =_xlfn.XLOOKUP(R366,[1]UPC!$C:$C,[1]UPC!$A:$A,"???",0) -> 7301 | T366: 59.99 | V366: =_xlfn.XLOOKUP(R366,[1]UPC!$C:$C,[1]UPC!$E:$E,"???",0) -> Fuschia | W366: =_xlfn.XLOOKUP(R366,[1]UPC!$C:$C,[1]UPC!$F:$F,"???",0) -> X Large | AA366: =_xlfn.XLOOKUP(AB366,'Bloomingdale''s Outlet'!C:C,'Bloomingdale''s Outlet'!B:B,"???",0) -> CI | AB366: 195 | AC366: 1 | AD366: D

Sheet INVOICE
G1: ASN
A2: Account | G2: BOL
A3: PO Number | B3: Cancel Date | C3: Store # | D3: Vendor Style | E3: Color | F3: Size | G3: UPC/EAN | H3: Qty | J3: INVOICE | K3: Store #
A4: 7335484 | B4: 44602 | C4: 38 | D4: 7301 | E4: Black | F4: X Small | G4: 810094067335 | H4: 1
E5: Deep Royal | F5: X Small | G5: 810094067380 | H5: 1
E6: Fuschia | F6: X Small | G6: 810094067434 | H6: 1
C7: 75 | D7: WO-7223 | E7: Black | F7: X Small | G7: 810081709163 | H7: 1
E8: Deep Royal | F8: X Small | G8: 810094066604 | H8: 1
C9: 76 | D9: WO-7223 | E9: Black | F9: X Small | G9: 810081709163 | H9: 2
E10: Deep Royal | F10: X Small | G10: 810094066604 | H10: 2
D11: 7301 | E11: Black | F11: X Small | G11: 810094067335 | H11: 1
E12: Deep Royal | F12: X Small | G12: 810094067380 | H12: 1
E13: Fuschia | F13: X Small | G13: 810094067434 | H13: 1
C14: 151 | D14: WO-7223 | E14: Black | F14: X Small | G14: 810081709163 | H14: 2
E15: Deep Royal | F15: X Small | G15: 810094066604 | H15: 2
D16: 7301 | E16: Deep Royal | F16: X Small | G16: 810094067380 | H16: 1
E17: Fuschia | F17: X Small | G17: 810094067434 | H17: 1
C18: 152 | D18: WO-7223 | E18: Black | F18: X Small | G18: 810081709163 | H18: 1
E19: Deep Royal | F19: X Small | G19: 810094066604 | H19: 1
D20: 7301 | E20: Deep Royal | F20: X Small | G20: 810094067380 | H20: 1
E21: Fuschia | F21: X Small | G21: 810094067434 | H21: 1
C22: 153 | D22: WO-7223 | E22: Black | F22: X Small | G22: 810081709163 | H22: 1
E23: Deep Royal | F23: X Small | G23: 810094066604 | H23: 1
D24: 7301 | E24: Black | F24: X Small | G24: 810094067335 | H24: 1
E25: Deep Royal | F25: X Small | G25: 810094067380 | H25: 1
E26: Fuschia | F26: X Small | G26: 810094067434 | H26: 1
C27: 154 | D27: 7301 | E27: Black | F27: X Small | G27: 810094067335 | H27: 1
E28: Deep Royal | F28: X Small | G28: 810094067380 | H28: 1
E29: Fuschia | F29: X Small | G29: 810094067434 | H29: 1
C30: 155 | D30: WO-7223 | E30: Black | F30: X Small | G30: 810081709163 | H30: 1
E31: Deep Royal | F31: X Small | G31: 810094066604 | H31: 1
D32: 7301 | E32: Black | F32: X Small | G32: 810094067335 | H32: 1
E33: Deep Royal | F33: X Small | G33: 810094067380 | H33: 1
E34: Fuschia | F34: X Small | G34: 810094067434 | H34: 1
C35: 160 | D35: WO-7223 | E35: Black | F35: X Small | G35: 810081709163 | H35: 2
E36: Deep Royal | F36: X Small | G36: 810094066604 | H36: 2
D37: 7301 | E37: Black | F37: X Small | G37: 810094067335 | H37: 2
E38: Deep Royal | F38: X Small | G38: 810094067380 | H38: 2
E39: Fuschia | F39: X Small | G39: 810094067434 | H39: 2
C40: 161 | D40: WO-7223 | E40: Black | F40: X Small | G40: 810081709163 | H40: 2
...

Sheet Packing List
A2: Account
A3: PO Number | B3: Cancel Date | C3: DC | D3: Store # | E3: Vendor Style | F3: Color | G3: Retail Price | H3: Size | I3: UPC/EAN | J3: Qty
A4: 7335484 | B4: 44602 | C4: CI | D4: 194 | E4: WO-7223 | F4: Deep Royal | G4: 59.99 | H4: X Small | I4: 810094066604 | J4: 1
H5: Small | I5: 810094066611 | J5: 1
H6: Medium | I6: 810094066628 | J6: 2
H7: Large | I7: 810094066635 | J7: 1
H8: X Large | I8: 810094066642 | J8: 1
F9: Deep Royal Total | J9: 6
D10: 195 | E10: WO-7223 | F10: Deep Royal | G10: 59.99 | H10: X Small | I10: 810094066604 | J10: 1
H11: Small | I11: 810094066611 | J11: 1
H12: Medium | I12: 810094066628 | J12: 2
H13: Large | I13: 810094066635 | J13: 1
H14: X Large | I14: 810094066642 | J14: 1
F15: Deep Royal Total | J15: 6
C16: CI Total | J16: 12
C17: CL | D17: 75 | E17: WO-7223 | F17: Deep Royal | G17: 59.99 | H17: X Small | I17: 810094066604 | J17: 1
H18: Small | I18: 810094066611 | J18: 1
H19: Medium | I19: 810094066628 | J19: 2
H20: Large | I20: 810094066635 | J20: 1
H21: X Large | I21: 810094066642 | J21: 1
F22: Deep Royal Total | J22: 6
D23: 76 | E23: WO-7223 | F23: Deep Royal | G23: 59.99 | H23: X Small | I23: 810094066604 | J23: 2
H24: Small | I24: 810094066611 | J24: 2
H25: Medium | I25: 810094066628 | J25: 4
H26: Large | I26: 810094066635 | J26: 2
H27: X Large | I27: 810094066642 | J27: 2
F28: Deep Royal Total | J28: 12
C29: CL Total | J29: 18
C30: HA | D30: 190 | E30: WO-7223 | F30: Deep Royal | G30: 59.99 | H30: X Small | I30: 810094066604 | J30: 1
H31: Small | I31: 810094066611 | J31: 1
H32: Medium | I32: 810094066628 | J32: 2
H33: Large | I33: 810094066635 | J33: 1
H34: X Large | I34: 810094066642 | J34: 1
F35: Deep Royal Total | J35: 6
C36: HA Total | J36: 6
C37: HU | D37: 170 | E37: WO-7223 | F37: Deep Royal | G37: 59.99 | H37: X Small | I37: 810094066604 | J37: 1
H38: Small | I38: 810094066611 | J38: 1
H39: Medium | I39: 810094066628 | J39: 2
H40: Large | I40: 810094066635 | J40: 1
H41: X Large | I41: 810094066642 | J41: 1
...

Sheet Order Checking Report
A2: Account
A3: PO Number | B3: Ship Dates | C3: Cancel Date | D3: Vendor Style | E3: Unit Price | F3: Retail Price | G3: Color | H3: Size | I3: UPC/EAN | J3: Qty
A4: 7335484 | B4: (blank) | C4: 44602 | D4: WO-7223 | E4: 30 | F4: 59.99 | G4: Black | H4: X Small | I4: 810081709163 | J4: 18
H5: Small | I5: 810081709170 | J5: 18
H6: Medium | I6: 810081709187 | J6: 36
H7: Large | I7: 810081709194 | J7: 18
H8: X Large | I8: 810094060268 | J8: 18
G9: Black Total | J9: 108
G10: Deep Royal | H10: X Small | I10: 810094066604 | J10: 18
H11: Small | I11: 810094066611 | J11: 18
H12: Medium | I12: 810094066628 | J12: 36
H13: Large | I13: 810094066635 | J13: 18
H14: X Large | I14: 810094066642 | J14: 18
G15: Deep Royal Total | J15: 108
D16: WO-7223 Total | J16: 216
D17: 7301 | E17: 30 | F17: 59.99 | G17: Black | H17: X Small | I17: 810094067335 | J17: 18
H18: Small | I18: 810094067342 | J18: 18
H19: Medium | I19: 810094067359 | J19: 36
H20: Large | I20: 810094067366 | J20: 18
H21: X Large | I21: 810094067373 | J21: 18
G22: Black Total | J22: 108
G23: Deep Royal | H23: X Small | I23: 810094067380 | J23: 18
H24: Small | I24: 810094067397 | J24: 18
H25: Medium | I25: 810094067403 | J25: 36
H26: Large | I26: 810094067410 | J26: 18
H27: X Large | I27: 810094067427 | J27: 18
G28: Deep Royal Total | J28: 108
G29: Fuschia | H29: X Small | I29: 810094067434 | J29: 18
H30: Small | I30: 810094067441 | J30: 18
H31: Medium | I31: 810094067458 | J31: 36
H32: Large | I32: 810094067465 | J32: 18
H33: X Large | I33: 810094067472 | J33: 18
G34: Fuschia Total | J34: 108
D35: 7301 Total | J35: 324
A36: Grand Total | J36: 540

Sheet Bloomingdale's
A4: Bloomingdale's
A6: Jewelry and Sunglass Vendors - see Routing Guide
A8: Distribution Centers listed below
B10: STORE | C10: ALPHA | I10: EFFECTIVE | L10: =VLOOKUP(AB2,#REF!,2,FALSE) -> #REF!
A11: DIV | B11: NUMBER | C11: DC LOC | D11: MALL NAME/STORE NAME | E11: ADDRESS | F11: CITY | G11: STATE | H11: ZIP | I11: DATE | J11: COMMENTS
A12: BLM | B12: 1 | C12: SC | D12: 59th St. - New York | E12: 1000 Third Ave | F12: New York | G12: NY | H12: 10022
A13: BLM | B13: 2 | C13: ST | D13: Boca Raton | E13: 5840 Glades Rd | F13: Boca Raton | G13: FL | H13: 33431 | I13: 03/29/2021 | J13: Serviced by ST, effective March 29, 2021
A14: BLM | B14: 3 | C14: ST | D14: Aventura | E14: 19555 Biscayne Blvd | F14: Aventura | G14: FL | H14: 33180 | I14: 03/29/2021 | J14: Serviced by ST, effective March 29, 2021
A15: BLM | B15: 4 | C15: SC | D15: Huntington | E15: 270 Walt Whitman Rd | F15: Huntington STA | G15: NY | H15: 11746
A16: BLM | B16: 5 | C16: SC | D16: Bergen County - Riverside | E16: 400 Hackensack Ave | F16: Hackensack | G16: NJ | H16: 07601
A17: BLM | B17: 6 | C17: SC | D17: Short Hills | E17: 1200 Morris Turnpike | F17: Short Hills | G17: NJ | H17: 07078
A18: BLM | B18: 7 | C18: CL | D18: Medinah Home | E18: 600 North Wabash Ave | F18: Chicago | G18: IL | H18: 60611
A19: BLM | B19: 8 | C19: CL | D19: North Michigan | E19: 900 NMichigan Ave | F19: Chicago | G19: IL | H19: 60611
A20: BLM | B20: 10 | C20: ST | D20: Palm Beach Gardens | E20: 3105 PGA Blvd | F20: Palm Beach Gardens | G20: FL | H20: 33410 | I20: 03/29/2021 | J20: Serviced by ST, effective March 29, 2021
A21: BLM | B21: 11 | C21: SW | D21: Chestnut Hill I & II | E21: 225 Boylston St | F21: Newton | G21: MA | H21: 02467
A22: BLM | B22: 12 | C22: SC | D22: White Plains | E22: 175 Bloomingdale Rd | F22: White Plains | G22: NY | H22: 10605
A23: BLM | B23: 14 | C23: JP | D23: Tysons Corner Flint | E23: 8100 Tysons Corner Center | F23: MC Lean | G23: VA | H23: 22102
A24: BLM | B24: 16 | C24: SC | D24: King Of Prussia | E24: 2 Rt 202 North 660 West Dekalb Pike | F24: King of Prussia | G24: PA | H24: 19406
A25: BLM | B25: 17 | C25: SC | D25: Willow Grove Park | E25: 2400 Moreland Park Rd | F25: Willow Grove | G25: PA | H25: 19090
A26: BLM | B26: 20 | C26: ST | D26: Orlando FL | E26: 4152 Conroy Rd | F26: Orlando | G26: FL | H26: 32839 | I26: 03/29/2021 | J26: Serviced by ST, effective March 29, 2021
A27: BLM | B27: 22 | C27: HA | D27: San Francisco | E27: 845 Market St | F27: San Francisco | G27: CA | H27: 94103
A28: BLM | B28: 24 | C28: SC | D28: Bridgewater | E28: 410 Commons Way | F28: Bridgewater | G28: NJ | H28: 08807
A29: BLM | B29: 26 | C29: CL | D29: Old Orchard | E29: 4963 Old Orchard Center | F29: Skokie | G29: IL | H29: 60077
A30: BLM | B30: 27 | C30: SC | D30: Roosevelt Field | E30: 630 Old Country Rd | F30: Garden City | G30: NY | H30: 11530
A31: BLM | B31: 28 | C31: CI | D31: Century City CA | E31: 10250 Santa Monica Blvd | F31: Los Angeles | G31: CA | H31: 90067
A32: BLM | B32: 29 | C32: CI | D32: Sherman Oaks | E32: 14060 Riverside Dr | F32: Sherman Oaks | G32: CA | H32: 91423
A33: BLM | B33: 30 | C33: CI | D33: Newport Beach Fashion | E33: 701 Newport Center Dr | F33: Newport Beach | G33: CA | H33: 92660
A34: BLM | B34: 31 | C34: HA | D34: Stanford CA | E34: 1 Stanford Shopping Center | F34: Palo Alto | G34: CA | H34: 94304
A35: BLM | B35: 32 | C35: CI | D35: Beverly Center | E35: 8500 Beverly Blvd | F35: Los Angeles | G35: CA | H35: 90048
A36: BLM | B36: 34 | C36: JP | D36: Chevy Chase - Wisconsin | E36: 5300 Western Ave | F36: Chevy Chase | G36: MD | H36: 20815
A37: BLM | B37: 37 | C37: SC | D37: Willowbrook Place | E37: 1400 Willowbrook Mall | F37: Wayne | G37: NJ | H37: 07470
A38: BLM | B38: 46 | C38: SW | D38: Norwalk | E38: 100 North Water Street | F38: Norwalk | G38: CT | H38: 06854 | I38: 2/1/2020 | J38: Serviced by SW effective February 1, 2020
A39: BLM | B39: 50 | C39: SC | D39: Westchester Furniture Clearance | E39: 2 Saw Mill River Road | F39: Hawthorne | G39: NY | H39: 10532
A40: BLM | B40: 53 | C40: SC | D40: Soho | E40: 504 Broadway | F40: New York | G40: NY | H40: 10012
A41: BLM | B41: 55 | C41: ST | D41: Lenox Square | E41: 3393 Peachtree Rd NE | F41: Atlanta | G41: GA | H41: 30326
A42: BLM | B42: 57 | C42: HA | D42: Valley Fair | E42: 2847 Stevens Creek Blvd | F42: San Jose | G42: CA | H42: 95128 | I42: Spring 2020 | J42: New Store Opening
A43: BLM | B43: 58 | C43: CI | D43: Ala Moana | E43: 1450 Ala Moana Blvd Suite 1000 | F43: Honolulu | G43: HI | H43: 96814
A44: BLM | B44: 59 | C44: CI | D44: Santa Monica CA | E44: 315 Colorado Ave | F44: Santa Monica | G44: CA | H44: 90401
A45: BLM | B45: 60 | C45: CI | D45: Glendale Galleria | E45: 103 S. Brand Ave | F45: Glendale | G45: CA | H45: 91204
A46: BLM | B46: 61 | C46: CI | D46: San Diego - Fashion Valley | E46: 7057 Friars Rd | F46: San Diego | G46: CA | H46: 92108
...

Sheet Bloomingdale's Outlet
A5: Bloomingdale's Outlet
A7: Department 835 Fine Jewelry Vendors see Routing Guide
B9: ALPHA | C9: STORE | D9: MALL NAME/ | I9: EFFECTIVE
A10: DIV | B10: DC LOC | C10: NUMBER | D10: STORE NAME | E10: ADDRESS | F10: CITY | G10: STATE | H10: ZIP | I10: DATE | J10: COMMENTS | L10: =VLOOKUP(AB2,#REF!,2,FALSE) -> #REF!
A11: BOS | B11: JP | C11: 38 | D11: Potomac Mills Outlet | E11: 2700 Potomac Mills Circle | F11: Woodbridge | G11: VA | H11: 22192
A12: BOS | B12: CL | C12: 75 | D12: Woodfield Outlet | E12: 1488 East Golf Rd | F12: Schaumburg | G12: IL | H12: 60173
A13: BOS | B13: CL | C13: 76 | D13: Rosemont Outlet | E13: 5220 Rose Street | F13: Rosemont | G13: IL | H13: 60018
A14: BOS | B14: CL | C14: 142 | D14: Northbrook | E14: 145 Skokie Boulevard | F14: Northbrook | G14: IL | H14: 60062 | I14: Fall 2019 | J14: New Store Opening
A15: BOS | B15: SC | C15: 151 | D15: Bergen Town Center Outlet | E15: 260 Bergen Town Center | F15: Paramus | G15: NJ | H15: 07652
A16: BOS | B16: SC | C16: 152 | D16: Gallery at Westbury | E16: 900 Old Country Road | F16: Garden City | G16: NY | H16: 11530
A17: BOS | B17: SC | C17: 153 | D17: Upper West Side | E17: 2085 Broadway | F17: New York | G17: NY | H17: 10023
A18: BOS | B18: SC | C18: 154 | D18: Liberty Place | E18: 1625 Chestnut Street | F18: Philadelphia | G18: PA | H18: 19103
A19: BOS | B19: SC | C19: 120 | D19: Riverhead | E19: 1771 West Main St | F19: Riverhead | G19: NY | H19: 11901
A20: BOS | B20: SC | C20: 155 | D20: Jersey Gardens | E20: 651 Kapkowski Road Unit 60 | F20: Elizabeth | G20: NJ | H20: 07201 | I20: Fall 2021 | J20: New Store Opening
A21: BOS | B21: ST | C21: 160 | D21: Sawgrass Mills Outlet | E21: 12801 W Sunrise Blvd | F21: Sunrise | G21: FL | H21: 33323 | I21: 44284 | J21: Serviced by ST, effective March 29, 2021
A22: BOS | B22: ST | C22: 161 | D22: Dolphin Outlet | E22: 11401 NW 12th Street | F22: Miami | G22: FL | H22: 33172 | I22: 44284 | J22: Serviced by ST, effective March 29, 2021
A23: BOS | B23: ST | C23: 162 | D23: Miromar Outlet | E23: 10801 Corkscrew Rd #163 | F23: Estero | G23: FL | H23: 33928 | I23: 44284 | J23: Serviced by ST, effective March 29, 2021
A24: BOS | B24: HU | C24: 170 | D24: Shops at Park Lane | E24: 8180 Park Lane Suite C140 | F24: Park Lane | G24: TX | H24: 75231
A25: BOS | B25: HU | C25: 171 | D25: Paragon Grand Prairie | E25: 120 & Great Southwest Pkwy | F25: Grand Prairie | G25: TX | H25: 75052
A26: BOS | B26: SW | C26: 180 | D26: Wrentham Outlet | E26: One Premium Outlets Blvd | F26: Wrentham | G26: MA | H26: 02093
A27: BOS | B27: SW | C27: 181 | D27: Merrimack Outlets | E27: 80 Premium Outlets Suite 0599 | F27: Merrimack | G27: NH | H27: 03054
A28: BOS | B28: HA | C28: 190 | D28: Paragon Livermore Valley | E28: 3130 Livermore Outlets Drive | F28: Livermore | G28: CA | H28: 94551
A29: BOS | B29: CI | C29: 191 | D29: Mission Valley | E29: 1646 Camino del Rio North Suite FSU13 | F29: San Diego | G29: CA | H29: 92108
A30: BOS | B30: CI | C30: 192 | D30: Outlets at Orange Center | E30: 20 City Boulevard West | F30: Orange | G30: CA | H30: 92868
A31: BOS | B31: CI | C31: 193 | D31: Beverly Connection Center | E31: 100 North La Cieniga Boulevard | F31: Los Angeles | G31: CA | H31: 90048
A32: BOS | B32: CI | C32: 194 | D32: Metro Pointe | E32: 901 South Coast Drive | F32: Costa Mesa | G32: CA | H32: 92626 | I32: Fall 2019 | J32: New Store Opening
A33: BOS | B33: CI | C33: 195 | D33: Woodland Hills | E33: 21494 Victory Blvd | F33: Woodland Hills | G33: CA | H33: 91367 | I33: Spring 2020 | J33: New Store Opening
A34: BOS | B34: CI | C34: 57 | D34: Los Angeles Pool Stock | E34: 15541 East Gale Ave | F34: City of Industry | G34: CA | H34: 91745
A35: BOS | B35: SC | C35: 56 | D35: Upper West Side Pool Stock | E35: 500 Meadowlands Pkwy | F35: Secaucus | G35: NJ | H35: 07094
A36: BOS | B36: CL | C36: 89 | D36: Minooka Pool Stock | E36: 601 Midpoint Road | F36: Minooka | G36: IL | H36: 60447
A37: BOS | B37: GN | C37: 80 | D37: Gandy Pool Stock | E37: 4130 W Gandy Blvd | F37: Tampa | G37: FL | H37: 33611 | I37: 44193 | J37: Closing Spring 2021
A38: BOS | B38: HA | C38: 66 | D38: Hayward Pool Stock | E38: 28701 Hall Rd | F38: Hayward | G38: CA | H38: 94545
A39: BOS | B39: HU | C39: 69 | D39: Houston Pool Stock | E39: 2103 Ernestine | F39: Houston | G39: TX | H39: 77023
A40: BOS | B40: JP | C40: 79 | D40: Joppa Pool Stock | E40: 3300 Fashion Way | F40: Joppa | G40: MD | H40: 21085
A41: BOS | B41: SC | C41: 78 | D41: Secaucus Pool Stock | E41: 500 Meadowlands Pkwy | F41: Secaucus | G41: NJ | H41: 07094
A42: BOS | B42: SW | C42: 84 | D42: South Windsor Pool Stock | E42: 301 Governors Highway | F42: South Windsor | G42: CT | H42: 06074
A43: BOS | B43: CD | C43: 138 | D43: Cheshire Pool Stock/Customer Fulfillment Center | E43: 475 Knotter Dr | F43: Cheshire | G43: CT | H43: 06410 | I43: 07/29/20
A44: BOS | B44: CD | D44: Cheshire DC | E44: 475 Knotter Dr | F44: Cheshire | G44: CT | H44: 06410
A45: BOS | B45: CI | D45: Los Angeles DC | E45: 15541 East Gale Ave | F45: City of Industry | G45: CA | H45: 91745
A46: BOS | B46: CL | D46: Minooka DC | E46: 601 Midpoint Road | F46: Minooka | G46: IL | H46: 60447
...

Sheet Shipping
A1: Store # | B1: Store Name | C1: Store Address | D1: DC # | E1: DC Name | F1: DC Address | G1: Poolstock #
A2: 38 | B2: Potomac | C2: 2700 Potomic Mills Circle, Woodbridge, VA 22192 | D2: 0264 | E2: Joppa DC | F2: 3300 Fashion Way, Joppa, MD 21085 | G2: 0268
A3: 75 | B3: Woodfield | C3: 1450 East Golf Road, Schaumburg, IL 60173 | D3: 0297 | E3: Minooka DC | F3: 601 Midpoint Rd, Minooka, IL 60447 | G3: 0298
A4: 76 | B4: Rosemont | C4: 5220 Fashion Outlet Way, Suite 2005, Rosemont, IL 60018 | D4: 89 | E4: Minooka | F4: 601 Midpoint Road, Minooka, IL 60447
A5: 142 | B5: Northbrook | C5: 145 Skokie Blvd, Northbrook, IL 60062 | E5: Minooka | F5: 601 Midpoint Road, Minooka, IL 60447
A6: 120 | B6: Riverhead | C6: 1771 West Main Street, Suite 912, Riverhead, NY 11901 | E6: Secaucus DC | F6: 500 Meadowlands Pkwy, Secaucus, NJ 07094
A7: 151 | B7: Bergen | C7: 260 Bergen Town Center, Paramus, NJ 07652 | D7: 0012 | E7: Secaucus DC | F7: 500 Meadowlands Pkwy, Secaucus, NJ 07094 | G7: 0106
A8: 152 | B8: Westbury | C8: 1050 Old Country Road, Garden City, NY 11530 | D8: 0012 | E8: Secaucus DC | F8: 500 Meadowlands Pkwy, Secaucus, NJ 07094 | G8: 0106
A9: 153 | B9: Upper West Side | C9: 2085 Broadway, New York, NY 10023 | E9: Secaucus DC | F9: 500 Meadowlands Pkwy, Secaucus, NJ 07094
A10: 154 | B10: Liberty Place | C10: 1625 Chestnut St Suite 240-248, Philadelphia, PA 19103 | E10: Secaucus DC | F10: 500 Meadowlands Pkwy, Secaucus, NJ 07094
A11: 160 | B11: Sawgrass | C11: 12801 W. Sunrise Blvd, Sunrise, FL 33323 | D11: 0964 | E11: Gandy DC | F11: 4130 Gandy Blvd, Tampa, FL 33611 | G11: 0963
A12: 161 | B12: Dolphin | C12: 11431 N.W.12th Street D101, Miami, FL 33172 | D12: 0964 | E12: Gandy DC | F12: 4130 Gandy Blvd, Tampa, FL 33611 | G12: 0963
A13: 162 | B13: Miromar | C13: 10801 Corkscrew Road #163, Estero, FL 33928 | D13: 0964 | E13: Gandy DC | F13: 4130 Gandy Blvd, Tampa, FL 33611 | G13: 0963
A14: 170 | B14: Park Lane | C14: 8180 Park Lane, Suite #C140, Park Lane, Texas 75231 | D14: 0944 | E14: Houston DC | F14: 2103 Ernestine, Houston, TX 77023 | G14: 0943
A15: 171 | B15: Grand Prairie | C15: 2950 W. Interstate 20, Suite 500, Grand Prarie, Texas 75052 | D15: 0944 | E15: Houston DC | F15: 2103 Ernestine, Houston, TX 77023 | G15: 0943
A16: 180 | B16: Wrentham | C16: One Premium Outlets Blvd. PL-5, Wrentham, MA 02093 | D16: 0251 | E16: South Windsor DC | F16: 301 Governor's Hwy, South Windsor, CT 06074 | G16: 0254
A17: 181 | B17: Merrimack | C17: 80 Premium Outlets Blvd Suite 0599, Merrimack, NH 03054 | D17: 0251 | E17: South Windsor DC | F17: 301 Governor's Hwy, South Windsor, CT 06074 | G17: 0254
A18: 190 | B18: Livermore | C18: 3130 Livermore Outlets Drive, Livermore, CA 94551 | D18: 0940 | E18: Hayward DC | F18: 28701 Hall Rd, Hayward, CA 94545 | G18: 0939
A19: 191 | B19: Mission Valley | C19: 1646 Camino del Rio North Suite FSU13, San Diego, CA 92108 | E19: City of Industry | F19: 15541 East Gale Avenue, City of Industry, CA 91745
A20: 192 | B20: Outlets at Orange Center | C20: 20 City Blvd west, Orange, CA, 92868 | E20: City of Industry | F20: 15541 East Gale Avenue, City of Industry, CA 91745
A21: 194 | B21: Metro Pointe | C21: 901-B South Coast Drive, Suite 150, Costa Mesa, CA 92626 | E21: City of Industry | F21: 15541 East Gale Avenue, City of Industry, CA 91745
A22: 195 | B22: Woodland Hills | C22: 21494 Victory Blvd Woodland Hills, CA 91367 | E22: City of Industry | F22: 15541 East Gale Avenue, City of Industry, CA 91745
A23: 79 | B23: Joppa DC Pool Stock | C23: 3300 Fashion Way, Joppa, MD 21085
A24: 89 | B24: Minooka DC Pool Stock | C24: 601 Midpoint Rd, Minooka, IL 60447
A25: 89 | B25: Minooka DC Pool Stock | C25: 601 Midpoint Rd, Minooka, IL 60447
A26: 89 | B26: Minooka DC Pool Stock | C26: 601 Midpoint Rd, Minooka, IL 60447
A27: 78 | B27: Secaucus DC Pool Stock | C27: 500 Meadowlands Pkwy, Secaucus, NJ 07094
A28: 78 | B28: Secaucus DC Pool Stock | C28: 500 Meadowlands Pkwy, Secaucus, NJ 07094
A29: 78 | B29: Secaucus DC Pool Stock | C29: 500 Meadowlands Pkwy, Secaucus, NJ 07094
A30: 56 | B30: Secaucus DC Pool Stock | C30: 500 Meadowlands Pkwy, Secaucus, NJ 07094
A31: 78 | B31: Secaucus DC Pool Stock | C31: 500 Meadowlands Pkwy, Secaucus, NJ 07094
A32: 80 | B32: Gandy DC Pool Stock | C32: 4130 Gandy Blvd, Tampa, FL 33611
A33: 80 | B33: Gandy DC Pool Stock | C33: 4130 Gandy Blvd, Tampa, FL 33611
A34: 80 | B34: Gandy DC Pool Stock | C34: 4130 Gandy Blvd, Tampa, FL 33611
... A43: 57 | B43: City of Industry Pool Stock | C43: 15541 East Gale Avenue, City of Industry, CA 91745
